Workbook
Name GroupA: 'Danh muc HH'!$B$107:$B$295
Name GroupB: 'Danh muc HH'!$B$297:$B$493
Name GroupC: 'Danh muc HH'!$B$495:$B$737
Name GroupD: 'Danh muc HH'!$B$739:$B$943
Name GroupE: 'Danh muc HH'!$B$945:$B$1096
Name GroupF: 'Danh muc HH'!$B$1098:$B$1215
Name GroupG: 'Danh muc HH'!$B$1217:$B$1373
Name GroupH: 'Danh muc HH'!$B$1375:$B$1533
Name GroupI: 'Danh muc HH'!$B$1535:$B$1650
Name GroupK: 'Danh muc HH'!$B$1652:$B$1808
Name GroupL: 'Danh muc HH'!$B$1810:$B$1945
Name GroupM: 'Danh muc HH'!$B$1947:$B$2130
Name GroupN: 'Danh muc HH'!$B$2132:$B$2294
Name GroupO: 'Danh muc HH'!$B$2296:$B$2421
Name GroupP: 'Danh muc HH'!$B$2423:$B$2616
Name GroupR: 'Danh muc HH'!$B$2618:$B$2735
Name GroupS: 'Danh muc HH'!$B$2737:$B$2858
Name GroupTH: 'Danh muc HH'!$B$2860:$B$3859
Name NHOMHANG: 'Danh muc HH'!$I$2:$I$20
Name NUMB: 'Danh muc HH'!$B$2:$B$105

Sheet Table 1
A1: DANH MỤC SẢN PHẨM ZALO: 0938 305 325 - 0909 23 99 10 - 0906 73 47 67 Tel: 3868 4225 - 3868 4469
B2: TênĐVT Giá bán | I2: TênĐVT Giá bán
A3: 1 | B3: 3B chai (C/50v) MK | D3: Chai | F3: 26.5 | H3: 53 | I3: An Nữ Đan | J3: Chai | K3: 121
A4: 2 | B4: 3B PV (H/100v) | D4: Hộp | F4: 37 | H4: 54 | I4: An Tâm Ngủ Ngon | J4: Hộp | K4: 142
A5: 3 | B5: 3B rẻ (H/100V)-DAKTIN | D5: Hộp | F5: 13 | H5: 55 | I5: An trĩ vương | J5: Hộp | K5: 157
A6: 4 | B6: 3B vĩ (H/100v) MK | D6: Hộp | F6: 61.8 | H6: 56 | I6: An Trĩ Vương Gel | J6: Tube | K6: 76
A7: 5 | B7: A 5000IU (H/100v) | D7: Hộp | F7: 25 | H7: 57 | I7: An triệu (lớn) 100ML | J7: Chai | K7: 33
A8: 6 | B8: Acemol 325 (C/40v) | D8: Chai | F8: 9.5 | H8: 58 | I8: An triệu (nhỏ) 60ml | J8: Chai | K8: 19
A9: 7 | B9: Acemuc 100 kids | D9: Hộp | F9: 52 | H9: 59 | I9: Antot - IQ | J9: Hộp | K9: 40
A10: 8 | B10: Acemuc 200-VIEN | D10: Hộp | F10: 66 | H10: 60 | I10: Áo đình ( Không nhận hàng đổi trả ) | J10: Hộp | K10: 337
A11: 9 | B11: Ace-tazolamic (H/100V) | D11: Hộp | F11: 92 | H11: 61 | I11: Apirin 81 VDP-Vĩ | J11: Hộp | K11: 13
A12: 10 | B12: Ace-tyl 200 vĩ 2/9 | D12: Hộp | F12: 50 | H12: 62 | I12: Apirin PH8 -Mekophar | J12: Hộp | K12: 85
A13: 11 | B13: Ace-tyl chai 2/9 (C/80v) | D13: Chai | F13: 38 | H13: 63 | I13: Apitim | J13: Hộp | K13: 21
A14: 12 | B14: Acetyl GÓI ( 2/9) (H/30 gói) | D14: Hộp | F14: 33.7 | H14: 64 | I14: Aquadetrim -K2 VN | J14: Chai | K14: 40
... A54: 52 | B54: An Bảo Nước | D54: Chai | F54: 36 | H54: 104 | I54: Bạch ngân PV-125ML | J54: Chai | K54: 40
B55: TênĐVT Giá bán | I55: TênĐVT Giá bán
A56: 105 | B56: Bách Xà | D56: Hộp | F56: 98 | H56: 157 | I56: Bisolvon -Vĩ | J56: Hộp | K56: 56
A57: 106 | B57: Bài Thạch ĐN | D57: Chai | F57: 45 | H57: 158 | I57: Biviflu -CHAI | J57: Chai | K57: 305
A58: 107 | B58: Bảo thanh ngậm (H/20 vỉ) xanh | D58: Hộp | F58: 148 | H58: 159 | I58: Biviflu -F | J58: Hộp | K58: 63
A59: 108 | B59: Bảo thanh ngậm ko đường (H/20 vỉ) | D59: Hộp | F59: 198 | H59: 160 | I59: BKLK | J59: Hộp | K59: 151
A60: 109 | B60: Bảo thanh siro | D60: Chai | F60: 44 | H60: 161 | I60: BKLK- cây | J60: Cây | K60: 15.5
A61: 110 | B61: Bảo Thanh siro TE | D61: Hộp | F61: 32.5 | H61: 162 | I61: Bổ gân tê bại | J61: Chai | K61: 23.5
A62: 111 | B62: Bảo tú lệ ( K nhận đổi trả - Tăng giá) | D62: Hộp | F62: 117 | H62: 163 | I62: Bổ khí thông huyết BVP (H/30v) | J62: Hộp | K62: 39
A63: 112 | B63: Bảo xuân Tím | D63: Hộp | F63: 136 | H63: 164 | I63: Bổ phế - siro | J63: Chai | K63: 43
A64: 113 | B64: Bảo Xuân Vàng | D64: Hộp | F64: 112 | H64: 165 | I64: Bổ phế - siro K0 đường NH | J64: Chai | K64: 55
A65: 114 | B65: Bar - lớn (C/180v) (không nhận đổi tr | D65: Lọ | F65: 57.5 | H65: 166 | I65: Bổ phế - viên (H/24v) | J65: Hộp | K65: 22
A66: 115 | B66: Bar - nhỏ (C/60v) | D66: Lọ | F66: 22 | H66: 167 | I66: Bổ phế Chỉ khái Lộ -TT | J66: Chai | K66: 29
A67: 116 | B67: Bảy màu Bình Thuận | D67: Lox | F67: 69 | H67: 168 | I67: Bổ Thận Âm (C/240v) OPC | J67: Chai | K67: 39.5
... A107: 156 | B107: Bisolvon SR | D107: Chai | F107: 34 | H107: 208 | I107: Calci hasan sủi | J107: Tuýp | K107: 46
B108: TênĐVT Giá bán | I108: TênĐVT Giá bán
A109: 209 | B109: Calci sủi BOSTON | D109: Tube | F109: 44 | H109: 261 | I109: Cevinton Fort (H/30v) | J109: Hộp | K109: 35
A110: 210 | B110: Calcigenol | D110: Chai | F110: 27 | H110: 262 | I110: Cezinate 250 (TW25) (H/10v) | J110: Hộp | K110: 24.6
A111: 211 | B111: Calcitriol Hà Tây | D111: Hộp | F111: 19 | H111: 263 | I111: Cezinate 500 (TW25) (H/20v)-LỚN | J111: Hộp | K111: 65
A112: 212 | B112: Cảm xuyên hương | D112: Hộp | F112: 39 | H112: 264 | I112: Chè Thái Bình- LỚN | J112: Bịch | K112: 84
A113: 213 | B113: Cao bạch hổ - lọ | D113: Lọ | F113: 21.5 | H113: 265 | I113: Choliver HG | J113: Tube | K113: 30.5
A114: 214 | B114: Captopril 25 -DMC | D114: Hộp | F114: 46 | H114: 266 | I114: Chức Năng Gan BN | J114: Hộp | K114: 65
A115: 215 | B115: Captoril 25mg QUẬN 4 | D115: Hộp | F115: 10 | H115: 267 | I115: Cicatrex | J115: Tube | K115: 35
A116: 216 | B116: Carbogast (H/30v) | D116: Hộp | F116: 38 | H116: 268 | I116: Cidetuss | J116: Hộp | K116: 85
A117: 217 | B117: Carbomango ( NAM VIỆT ) | D117: Chai | F117: 8 | H117: 269 | I117: CIM (viên) - DMK4/2021 | J117: Hộp | K117: 14
A118: 218 | B118: Carbotrim - DL (H/80v) | D118: Hộp | F118: 50 | H118: 270 | I118: CIM siro > 180ml | J118: Chai | K118: 37
...

Sheet Danh Muc
A1: STT | B1: Tên Sản Phẩm | C1: ĐVT | D1: Giá bán
A2: 1 | B2: 3B chai (C/50v) MK | C2: Chai | D2: 26.5
A3: 2 | B3: 3B PV (H/100v) | C3: Hộp | D3: 37
A4: 3 | B4: 3B rẻ (H/100V)-DAKTIN | C4: Hộp | D4: 13
A5: 4 | B5: 3B vĩ (H/100v) MK | C5: Hộp | D5: 61.8
A6: 5 | B6: A 5000IU (H/100v) | C6: Hộp | D6: 25
A7: 6 | B7: Acemol 325 (C/40v) | C7: Chai | D7: 9.5
A8: 7 | B8: Acemuc 100 kids | C8: Hộp | D8: 52
A9: 8 | B9: Acemuc 200-VIEN | C9: Hộp | D9: 66
A10: 9 | B10: Ace-tazolamic (H/100V) | C10: Hộp | D10: 92
A11: 10 | B11: Ace-tyl 200 vĩ 2/9 | C11: Hộp | D11: 50
A12: 11 | B12: Ace-tyl chai 2/9 (C/80v) | C12: Chai | D12: 38
A13: 12 | B13: Acetyl GÓI ( 2/9) (H/30 gói) | C13: Hộp | D13: 33.7
... A1041: 1040 | B1041: Silkron HQ | C1041: Tube | D1041: 17.4

Sheet QLSP
I1: Tổng Tiền Nhập | J1: =SUM(H7:H24) -> 9802.5
I2: Lãi Sỉ + Lẻ
A6: STT | B6: Tên sản phẩm | C6: Đơn vị tính | D6: Số Lượng | E6: Giá Nhập | F6: Giá Bán Sỉ | G6: Giá Bán Lẻ | H6: Thành Tiền | J6: Tên Sản Phẩm | K6: SL Bán Sỉ | L6: SL Bán Lẻ | M6: Thu Nhập Sỉ/Lẻ | N6: Tồn Kho | O6: Tiền Lãi Trên SP
B7: 3B chai (C/50v) MK | C7: Chai | D7: 5 | E7: 26.5 | F7: 27.5 | G7: 40 | H7: =E7*D7 -> 132.5 | J7: 3B chai (C/50v) MK | L7: 1 | M7: =F7*K7+G7*L7 -> 40 | N7: =D7-K7-L7 -> 4 | O7: =M7-H7 -> -92.5
B8: 3B PV (H/100v) | C8: Hộp | D8: 5 | E8: 37 | F8: 38 | G8: 60 | H8: =E8*D8 -> 185 | J8: 3B PV (H/100v) | K8: 5 | M8: =F8*K8+G8*L8 -> 190 | N8: =D8-K8-L8 -> 0 | O8: =M8-H8 -> 5
B9: 3B rẻ (H/100V)-DAKTIN | C9: Hộp | D9: 5 | E9: 13 | F9: 14 | G9: 30 | H9: =E9*D9 -> 65 | J9: 3B rẻ (H/100V)-DAKTIN | K9: 5 | M9: =F9*K9+G9*L9 -> 70 | N9: =D9-K9-L9 -> 0 | O9: =M9-H9 -> 5
B10: 3B vĩ (H/100v) MK | C10: Hộp | D10: 5 | E10: 61.8 | F10: 63 | G10: 72 | H10: =E10*D10 -> 309 | J10: 3B vĩ (H/100v) MK | K10: 5 | M10: =F10*K10+G10*L10 -> 315 | N10: =D10-K10-L10 -> 0 | O10: =M10-H10 -> 6
B11: A 5000IU (H/100v) | C11: Hộp | D11: 5 | E11: 25 | F11: 26 | G11: 40 | H11: =E11*D11 -> 125 | J11: A 5000IU (H/100v) | L11: 3 | M11: =F11*K11+G11*L11 -> 120 | N11: =D11-K11-L11 -> 2 | O11: =M11-H11 -> -5
B12: Acemol 325 (C/40v) | C12: Chai | D12: 5 | E12: 9.5 | F12: 10 | G12: 20 | H12: =E12*D12 -> 47.5 | J12: Acemol 325 (C/40v) | M12: =F12*K12+G12*L12 -> 0 | N12: =D12-K12-L12 -> 5 | O12: =M12-H12 -> -47.5
B13: Acemuc 100 kids | C13: Hộp | D13: 5 | E13: 52 | F13: 53 | G13: 58 | H13: =E13*D13 -> 260 | J13: Acemuc 100 kids | M13: =F13*K13+G13*L13 -> 0 | N13: =D13-K13-L13 -> 5 | O13: =M13-H13 -> -260
B14: Acemuc 200-VIEN | C14: Hộp | D14: 24 | E14: 66 | F14: 67 | G14: 80 | H14: =E14*D14 -> 1584 | J14: Acemuc 200-VIEN | K14: 10 | L14: 3 | M14: =F14*K14+G14*L14 -> 910 | N14: =D14-K14-L14 -> 11 | O14: =M14-H14 -> -674
B15: Ace-tazolamic (H/100V) | C15: Hộp | D15: 12 | E15: 92 | F15: 93 | G15: 105 | H15: =E15*D15 -> 1104 | J15: Ace-tazolamic (H/100V) | K15: 10 | L15: 2 | M15: =F15*K15+G15*L15 -> 1140 | N15: =D15-K15-L15 -> 0 | O15: =M15-H15 -> 36
B16: Ace-tyl 200 vĩ 2/9 | C16: Hộp | D16: 20 | E16: 50 | F16: 52 | G16: 77 | H16: =E16*D16 -> 1000 | J16: Ace-tyl 200 vĩ 2/9 | K16: 5 | L16: 3 | M16: =F16*K16+G16*L16 -> 491 | N16: =D16-K16-L16 -> 12 | O16: =M16-H16 -> -509
B17: Ace-tyl chai 2/9 (C/80v) | C17: Chai | D17: 10 | E17: 38 | F17: 40 | G17: 60 | H17: =E17*D17 -> 380 | J17: Ace-tyl chai 2/9 (C/80v) | K17: 5 | L17: 4 | M17: =F17*K17+G17*L17 -> 440 | N17: =D17-K17-L17 -> 1 | O17: =M17-H17 -> 60
B18: Acetyl GÓI ( 2/9) (H/30 gói) | C18: Hộp | D18: 20 | E18: 33.7 | F18: 35 | G18: 50 | H18: =E18*D18 -> 674 | J18: Acetyl GÓI ( 2/9) (H/30 gói) | K18: 12 | L18: 2 | M18: =F18*K18+G18*L18 -> 520 | N18: =D18-K18-L18 -> 6 | O18: =M18-H18 -> -154
B19: Ace-tyl vĩ MKP-CT | C19: Hộp | D19: 20 | E19: 44 | F19: 47 | G19: 65 | H19: =E19*D19 -> 880 | J19: Ace-tyl vĩ MKP-CT | K19: 8 | L19: 1 | M19: =F19*K19+G19*L19 -> 441 | N19: =D19-K19-L19 -> 11 | O19: =M19-H19 -> -439
B20: Acigmentin 625-Minh Hải | C20: Hộp | D20: 30 | E20: 54 | F20: 58 | G20: 70 | H20: =E20*D20 -> 1620 | J20: Acigmentin 625-Minh Hải | K20: 20 | M20: =F20*K20+G20*L20 -> 1160 | N20: =D20-K20-L20 -> 10 | O20: =M20-H20 -> -460
B21: Acimentin 1G - MINH HẢI | C21: Hộp | D21: 10 | E21: 57 | F21: 60 | G21: 78 | H21: =E21*D21 -> 570 | J21: Acimentin 1G - MINH HẢI | L21: 10 | M21: =F21*K21+G21*L21 -> 780 | N21: =D21-K21-L21 -> 0 | O21: =M21-H21 -> 210
B22: Acy 200 -viên stda | C22: Hộp | D22: 11 | E22: 32 | F22: 35 | G22: 64 | H22: =E22*D22 -> 352 | J22: Acy 200 -viên stda | M22: =F22*K22+G22*L22 -> 0 | N22: =D22-K22-L22 -> 11 | O22: =M22-H22 -> -352
B23: Acyc lovir 200 (H/10v) DMK | C23: Hộp | D23: 3 | E23: 31.5 | F23: 33 | G23: 54 | H23: =E23*D23 -> 94.5 | J23: Acyc lovir 200 (H/10v) DMK | L23: 3 | M23: =F23*K23+G23*L23 -> 162 | N23: =D23-K23-L23 -> 0 | O23: =M23-H23 -> 67.5
B24: ACYCLOVIR 400 STD | C24: Hộp | D24: 5 | E24: 84 | F24: 86 | G24: 90 | H24: =E24*D24 -> 420 | J24: ACYCLOVIR 400 STD | L24: 5 | M24: =F24*K24+G24*L24 -> 450 | N24: =D24-K24-L24 -> 0 | O24: =M24-H24 -> 30

Sheet XNT
A1: STT | B1: Ngày/tháng/ năm | C1: Tên hàng hóa | D1: Đơn vị tính | E1: Số lượng | F1: Đơn giá | G1: Thành tiền | H1: Tồn kho ban đầu | I1: Tồn kho sau bán | J1: Ghi chú

Sheet Khach Hang
A1: STT | B1: Tên khách hàng | C1: Số điện thoại | D1: Địa chỉ | E1: Cọc TM/CK

Sheet Danh muc HH
A1: NHÓM | B1: Tên sản phẩm | C1: Đơn vị tính | D1: Giá Bán Sỉ | E1: Giá Bán Lẻ | I1: Nhóm Hàng
A2: NUMB | B2: 3B chai (C/50v) MK | C2: Chai | D2: 26500 | E2: =D2+15 -> 26515 | I2: NUMB
B3: 3B PV (H/100v) | C3: Hộp | D3: 37000 | E3: =D3+15 -> 37015 | I3: GroupA
B4: 3B rẻ (H/100V)-DAKTIN | C4: Hộp | D4: 13000 | E4: =D4+15 -> 13015 | I4: GroupB
B5: 3B vĩ (H/100v) MK | C5: Hộp | D5: 61800 | E5: =D5+15 -> 61815 | I5: GroupC
I6: GroupD
I7: GroupE
I8: GroupF
I9: GroupG
I10: GroupH
I11: GroupI
I12: GroupK
I13: GroupL
I14: GroupM
I15: GroupN
I16: GroupO
I17: GroupP
... I20: GroupTH
A107: GroupA | B107: A 5000IU (H/100v) | C107: Hộp | D107: 25000 | E107: =D107+15 -> 25015
B108: Acemol 325 (C/40v) | C108: Chai | D108: 9500 | E108: =D108+15 -> 9515
B109: Acemuc 100 kids | C109: Hộp | D109: 52000 | E109: =D109+15 -> 52015
B110: Acemuc 200-VIEN | C110: Hộp | D110: 66000 | E110: =D110+15 -> 66015
B111: Ace-tazolamic (H/100V) | C111: Hộp | D111: 92000 | E111: =D111+15 -> 92015
B112: Ace-tyl 200 vĩ 2/9 | C112: Hộp | D112: 50000 | E112: =D112+15 -> 50015
B113: Ace-tyl chai 2/9 (C/80v) | C113: Chai | D113: 38000 | E113: =D113+15 -> 38015
B114: Acetyl GÓI ( 2/9) (H/30 gói) | C114: Hộp | D114: 33700 | E114: =D114+15 -> 33715
B115: Ace-tyl vĩ MKP-CT | C115: Hộp | D115: 44000 | E115: =D115+15 -> 44015
B116: Acigmentin 625-Minh Hải | C116: Hộp | D116: 54000 | E116: =D116+15 -> 54015
B117: Acimentin 1G - MINH HẢI | C117: Hộp | D117: 57000 | E117: =D117+15 -> 57015
B118: Acy 200 -viên stda | C118: Hộp | D118: 32000 | E118: =D118+15 -> 32015
B119: Acyc lovir 200 (H/10v) DMK | C119: Hộp | D119: 31500 | E119: =D119+15 -> 31515
... B195: Azytex (Hộp) (H/100v) | C195: Hộp | D195: 19000 | E195: =D195+15 -> 19015
A297: GroupB | B297: B1 250mg DAKTIN | C297: Chai | D297: 17000 | E297: =D297+15 -> 17015
B298: B1-250 (C/100v c.a.p) - MK | C298: Chai | D298: 56500 | E298: =D298+15 -> 56515
B299: B1-250 (H/100v) MK | C299: Hộp | D299: 55000 | E299: =D299+15 -> 55015
B300: B1-50 (C/100v) MKF | C300: Chai | D300: 14500 | E300: =D300+15 -> 14515
B301: B1-50 Rẻ ( Lox 10c ) | C301: Lox | D301: 34000 | E301: =D301+15 -> 34015
B302: B2 Lọ nhí | C302: Lọ | D302: 3500 | E302: =D302+15 -> 3515
B303: B6 250mg PP | C303: Chai | D303: 21000 | E303: =D303+15 -> 21015
B304: B6-250 (vĩ) (H/100v) MK | C304: Hộp | D304: 44000 | E304: =D304+15 -> 44015
...

Sheet Hoa don
A2: Nhà Thuốc QUỲNH ANH | E2: HÓA ĐƠN BÁN HÀNG
E3: --------****---------
E4: Thuốc Tây & Vật Tư Y Tế
A5: ĐC: Bình Dương | E5: Trang Thiết Bị Ngành Y
A6: ĐT: 090 00000000
A8: Tên khách hàng: | C8: Nguyen Le Nhu Ngoc
A9: Địa chỉ: | C9: Lai Thieu
A10: Điện thoại: | C10: 0912123123
A12: TT | B12: NHÓM | C12: TÊN HÀNG | D12: ĐVT | E12: SL | F12: ĐƠN GIÁ | G12: THÀNH TIỀN
A13: 1 | B13: GroupA | C13: A 5000IU (H/100v) | D13: =IFERROR(VLOOKUP($C13,'Danh muc HH'!B2:D2758,2,0),"") -> Hộp | E13: 1 | F13: =IFERROR(VLOOKUP($C13,'Danh muc HH'!B2:D2758,3,0),"") -> 25000 | G13: =IFERROR(E13*F13,"") -> 25000
A14: 2 | B14: GroupE | C14: Ecoship ( Yaguchi) -H 20G | D14: =IFERROR(VLOOKUP($C14,'Danh muc HH'!B2:D2859,2,0),"") -> Hộp | E14: 3 | F14: =IFERROR(VLOOKUP($C14,'Danh muc HH'!B2:D2859,3,0),"") -> 152000 | G14: =IFERROR(E14*F14,"") -> 456000
A15: 3 | B15: GroupD | C15: Dạ hương vòi | D15: =IFERROR(VLOOKUP($C15,'Danh muc HH'!B2:D2860,2,0),"") -> Chai | E15: 4 | F15: =IFERROR(VLOOKUP($C15,'Danh muc HH'!B2:D2860,3,0),"") -> 31000 | G15: =IFERROR(E15*F15,"") -> 124000
A16: 4 | B16: GroupE | C16: Efelagin 500 sủi -TIỀN GIANG | D16: =IFERROR(VLOOKUP($C16,'Danh muc HH'!B2:D2861,2,0),"") -> Hộp | E16: 5 | F16: =IFERROR(VLOOKUP($C16,'Danh muc HH'!B2:D2861,3,0),"") -> 20000 | G16: =IFERROR(E16*F16,"") -> 100000
A17: 5 | B17: GroupF | C17: Fenofibrat 200 (H/30v) | D17: =IFERROR(VLOOKUP($C17,'Danh muc HH'!B2:D2862,2,0),"") -> Hộp | E17: 6 | F17: =IFERROR(VLOOKUP($C17,'Danh muc HH'!B2:D2862,3,0),"") -> 45000 | G17: =IFERROR(E17*F17,"") -> 270000
A18: 6 | B18: GroupF | C18: Farzincol - siro 90ml | D18: =IFERROR(VLOOKUP($C18,'Danh muc HH'!B2:D2863,2,0),"") -> Chai | E18: 2 | F18: =IFERROR(VLOOKUP($C18,'Danh muc HH'!B2:D2863,3,0),"") -> 24000 | G18: =IFERROR(E18*F18,"") -> 48000
A19: 7 | B19: GroupS | C19: Salonship | D19: =IFERROR(VLOOKUP($C19,'Danh muc HH'!B2:D2864,2,0),"") -> Hộp | E19: 7 | F19: =IFERROR(VLOOKUP($C19,'Danh muc HH'!B2:D2864,3,0),"") -> 168000 | G19: =IFERROR(E19*F19,"") -> 1176000
A20: 8 | B20: GroupG | C20: Gạc nhỏ | D20: =IFERROR(VLOOKUP($C20,'Danh muc HH'!B2:D2865,2,0),"") -> Gói | E20: 10 | F20: =IFERROR(VLOOKUP($C20,'Danh muc HH'!B2:D2865,3,0),"") -> 3000 | G20: =IFERROR(E20*F20,"") -> 30000
A21: 9 | B21: NUMB | C21: 3B PV (H/100v) | D21: =IFERROR(VLOOKUP($C21,'Danh muc HH'!B2:D2866,2,0),"") -> Hộp | E21: 2 | F21: =IFERROR(VLOOKUP($C21,'Danh muc HH'!B2:D2866,3,0),"") -> 37000 | G21: =IFERROR(E21*F21,"") -> 74000
A22: 10 | B22: GroupH | C22: Hà Thủ ô TW 3 3/2024 | D22: =IFERROR(VLOOKUP($C22,'Danh muc HH'!B2:D2867,2,0),"") -> Chai | E22: 5 | F22: =IFERROR(VLOOKUP($C22,'Danh muc HH'!B111:D2867,3,0),"") -> 76000 | G22: =IFERROR(E22*F22,"") -> 380000
A23: 11 | D23: =IFERROR(VLOOKUP($C23,'Danh muc HH'!B2:D2868,2,0),"") | F23: =IFERROR(VLOOKUP($C23,'Danh muc HH'!B112:D2868,3,0),"")
A24: 12 | D24: =IFERROR(VLOOKUP($C24,'Danh muc HH'!B5:D2869,2,0),"") | F24: =IFERROR(VLOOKUP($C24,'Danh muc HH'!B113:D2869,3,0),"")
A25: 13 | D25: =IFERROR(VLOOKUP($C25,'Danh muc HH'!B5:D2870,2,0),"") | F25: =IFERROR(VLOOKUP($C25,'Danh muc HH'!B114:D2870,3,0),"")
A26: 14 | D26: =IFERROR(VLOOKUP($C26,'Danh muc HH'!B5:D2871,2,0),"") | F26: =IFERROR(VLOOKUP($C26,'Danh muc HH'!B115:D2871,3,0),"")
A27: 15 | D27: =IFERROR(VLOOKUP($C27,'Danh muc HH'!B108:D2872,2,0),"") | F27: =IFERROR(VLOOKUP($C27,'Danh muc HH'!B116:D2872,3,0),"")
A28: 16 | D28: =IFERROR(VLOOKUP($C28,'Danh muc HH'!B108:D2873,2,0),"") | F28: =IFERROR(VLOOKUP($C28,'Danh muc HH'!B117:D2873,3,0),"")
A29: 17 | D29: =IFERROR(VLOOKUP($C29,'Danh muc HH'!B108:D2874,2,0),"") | F29: =IFERROR(VLOOKUP($C29,'Danh muc HH'!B118:D2874,3,0),"")
A30: 18 | D30: =IFERROR(VLOOKUP($C30,'Danh muc HH'!B111:D2875,2,0),"") | F30: =IFERROR(VLOOKUP($C30,'Danh muc HH'!B119:D2875,3,0),"")
A31: 19 | D31: =IFERROR(VLOOKUP($C31,'Danh muc HH'!B111:D2876,2,0),"") | F31: =IFERROR(VLOOKUP($C31,'Danh muc HH'!B120:D2876,3,0),"")
A32: 20 | D32: =IFERROR(VLOOKUP($C32,'Danh muc HH'!B111:D2877,2,0),"") | F32: =IFERROR(VLOOKUP($C32,'Danh muc HH'!B121:D2877,3,0),"")
A33: TỔNG CỘNG | E33: =SUM(E13:E32) -> 45 | G33: =SUM(G13:G32) -> 2683000
A35: Số tiền bằng chữ: | D35: =[1]!UNI(G33) -> Hai triệu sáu trăm tám mươi ba nghìn đồng
E37: =TODAY() -> 45463
A39: KHÁCH HÀNG | E39: NGƯỜI BÁN HÀNG

Sheet Sheet1
A1: 2229000 | B1: =[1]!UNI(A1) -> Hai triệu hai trăm hai mươi chín nghìn đồng
A2: 2683000 | B2: =[1]!UNI(A2) -> Hai triệu sáu trăm tám mươi ba nghìn đồng
